<?xml version="1.0" encoding="utf-8" ?>
<!-- =================================================================================== -->
<!-- |    This document was autogenerated by xacro from /home/e/ROS/Armbot/src/armbot_description/urdf/armbot.urdf.xacro | -->
<!-- |    EDITING THIS FILE BY HAND IS NOT RECOMMENDED                                 | -->
<!-- =================================================================================== -->
<!-- Open_Manipulator Chain -->
<robot name="armbot">
    <material name="black">
        <color rgba="0.0 0.0 0.0 1.0" />
    </material>
    <material name="white">
        <color rgba="1.0 1.0 1.0 1.0" />
    </material>
    <material name="red">
        <color rgba="0.8 0.0 0.0 1.0" />
    </material>
    <material name="blue">
        <color rgba="0.0 0.0 0.8 1.0" />
    </material>
    <material name="green">
        <color rgba="0.0 0.8 0.0 1.0" />
    </material>
    <material name="grey">
        <color rgba="0.5 0.5 0.5 1.0" />
    </material>
    <material name="orange">
        <color rgba="1.0 0.423529411765 0.0392156862745 1.0" />
    </material>
    <material name="brown">
        <color rgba="0.870588235294 0.811764705882 0.764705882353 1.0" />
    </material>
    <!-- Base link -->
    <link name="base">
        <visual>
            <origin xyz="0 0 0" />
            <geometry>
                <mesh filename="package://armbot_description/meshes/base.obj" scale="0.01 0.01 0.01" />
            </geometry>
        </visual>
    </link>
    <link name="motors">
        <visual>
            <origin xyz="0 0 0.045" />
            <geometry>
                <mesh filename="package://armbot_description/meshes/link0.obj" scale="0.01 0.01 0.01" />
            </geometry>
        </visual>
    </link>
    <joint name="base_to_motors" type="continuous">
        <parent link="base" />
        <child link="motors" />
        <axis xyz="0 0 1" />
        <safety_controller k_position="1" k_velocity="1" soft_lower_limit="-1.57" soft_upper_limit="1.57" />
    </joint>
    <link name="link2_horizontal_bottom">
        <!--        <visual>-->
        <!--            <origin xyz="0 0 0" rpy="0 -${pi/2} 0"/>-->
        <!--            <geometry>-->
        <!--                <mesh filename="package://armbot_description/meshes/link1.obj" scale="0.01 0.01 0.01"/>-->
        <!--            </geometry>-->
        <!--        </visual>-->
        <visual>
            <origin rpy="0 -9.42477796077 0" xyz="0 0 0" />
            <geometry>
                <mesh filename="package://armbot_description/meshes/link2.obj" scale="0.01 0.01 0.01" />
            </geometry>
            <material name="grey" />
        </visual>
    </link>
    <joint name="motors_to_link2_horizontal_bottom" type="fixed">
        <parent link="motors" />
        <origin xyz="-0.0052 0.01 0.45" />
        <child link="link2_horizontal_bottom" />
    </joint>
    <link name="link3_vertical">
        <visual>
            <origin rpy="0 -1.57079632679 0" xyz="0 0 0" />
            <geometry>
                <mesh filename="package://armbot_description/meshes/link3.obj" scale="0.01 0.01 0.01" />
            </geometry>
            <material name="grey" />
        </visual>
    </link>
    <joint name="link2_horizontal_bottom_link3_vertical" type="continuous">
        <parent link="link2_horizontal_bottom" />
        <child link="link3_vertical" />
        <axis xyz="0 1 0" />
        <origin xyz="-0.5 0.01 0" />
        <safety_controller k_position="1" k_velocity="1" soft_lower_limit="-1.57" soft_upper_limit="1.57" />
    </joint>
    <link name="link4_horizontal_top_long">
        <visual>
            <origin xyz="0 0 0" />
            <geometry>
                <mesh filename="package://armbot_description/meshes/link4.obj" scale="0.01 0.01 0.01" />
            </geometry>
            <material name="grey" />
        </visual>
    </link>
    <joint name="link3_vertical_to_link4_horizontal_top_long" type="continuous">
        <parent link="link3_vertical" />
        <child link="link4_horizontal_top_long" />
        <axis xyz="0 1 0" />
        <origin xyz="0 0.085 2" />
        <safety_controller k_position="1" k_velocity="1" soft_lower_limit="-1.57" soft_upper_limit="1.57" />
    </joint>
    <link name="tool">
        <visual>
            <origin rpy="0 0 0" xyz="0 0 0" />
            <geometry>
                <mesh filename="package://armbot_description/meshes/tool.obj" scale="0.01 0.01 0.01" />
            </geometry>
            <material name="grey" />
        </visual>
    </link>
    <joint name="link4_horizontal_top_long_to_tool" type="fixed">
        <parent link="link4_horizontal_top_long" />
        <child link="tool" />
        <origin xyz="2.5 -0.1 0" />
    </joint>

    <transmission name="trans_base_to_motors">
        <type>transmission_interface/SimpleTransmission</type>
        <joint name="base_to_motors">
            <hardwareInterface>hardware_interface/EffortJointInterface</hardwareInterface>
        </joint>
        <actuator name="base_to_motors_motor">
            <hardwareInterface>hardware_interface/EffortJointInterface</hardwareInterface>
            <mechanicalReduction>1</mechanicalReduction>
        </actuator>
    </transmission>
    <transmission name="trans_link2_horizontal_bottom_link3_vertical">
        <type>transmission_interface/SimpleTransmission</type>
        <joint name="link2_horizontal_bottom_link3_vertical">
            <hardwareInterface>hardware_interface/EffortJointInterface</hardwareInterface>
        </joint>
        <actuator name="link2_horizontal_bottom_link3_vertical_motor">
            <hardwareInterface>hardware_interface/EffortJointInterface</hardwareInterface>
            <mechanicalReduction>1</mechanicalReduction>
        </actuator>
    </transmission>
    <transmission name="trans_link3_vertical_to_link4_horizontal_top_long">
        <type>transmission_interface/SimpleTransmission</type>
        <joint name="link3_vertical_to_link4_horizontal_top_long">
            <hardwareInterface>hardware_interface/EffortJointInterface</hardwareInterface>
        </joint>
        <actuator name="link3_vertical_to_link4_horizontal_top_long_motor">
            <hardwareInterface>hardware_interface/EffortJointInterface</hardwareInterface>
            <mechanicalReduction>1</mechanicalReduction>
        </actuator>
    </transmission>
    <gazebo>
        <plugin name="gazebo_ros_control" filename="libgazebo_ros_control.so">
            <robotNamespace>/</robotNamespace>
        </plugin>
    </gazebo>
</robot>