<?xml version="1.0" encoding="utf-8" ?>
<!-- This URDF was automatically created by SolidWorks to URDF Exporter! Originally created by Stephen Brawner (brawner@gmail.com)
     Commit Version: 1.6.0-4-g7f85cfe  Build Version: 1.6.7995.38578
     For more information, please see http://wiki.ros.org/sw_urdf_exporter -->
<robot name="armbot">
    <material name="Black">
        <color rgba="0 0 0 1" />
    </material>
    <material name="White">
        <color rgba="1 1 1 1" />
    </material>
    <material name="Grey">
        <color rgba="0.5 0.5 0.5 1" />
    </material>
    <material name="Blue">
        <color rgba="0.03 0.53 0.64 1" />
    </material>
    <material name="BlueLight">
        <color rgba="0.24 0.69 0.74 1" />
    </material>
    <material name="Yellow">
        <color rgba="0.42 0.40 0.15 1" />
    </material>
    <link name="world" />
    <joint name="joint1_world" type="fixed">
        <parent link="world" />
        <child link="base_link" />
    </joint>
    <link name="base_link">

<inertial>
            <origin xyz="0.0211202900240581 2.59775846179198E-11 0.00380052135150775" rpy="0 0 3.14" />
            <mass value="0.271570047216607" />
            <inertia ixx="0.000442541459178714" ixy="-7.61202510854808E-12" ixz="-5.27773157069647E-07" iyy="0.000555892462598209" iyz="5.63321075341317E-15" izz="0.000997118891006557" />
        </inertial>

        <visual>
            <origin xyz="0 0 0" rpy="0 0 3.14" />
            <geometry>
                <mesh filename="package://armbot_description/meshes/model_npoa/base_link.STL" />
            </geometry>
            <material name="Yellow" />
        </visual>
        <collision>
            <origin xyz="0 0 0" rpy="0 0 3.14" />
            <geometry>
                <mesh filename="package://armbot_description/meshes/model_npoa/base_link.STL" />
            </geometry>
        </collision>
    </link>
    <link name="link_1">

<inertial>
            <origin xyz="-0.00272155425407784 0.00011334099940661 0.0586724985336868" rpy="0 0 0" />
            <mass value="0.579092466366984" />
            <inertia ixx="0.000456587803138105" ixy="1.13087657027168E-07" ixz="-3.16702255632447E-06" iyy="0.000511771419629803" iyz="-1.37277769518059E-06" izz="0.000496840287124422" />
        </inertial>

        <visual>
            <origin xyz="0 0 0" rpy="0 0 0" />
            <geometry>
                <mesh filename="package://armbot_description/meshes/model_npoa/link_1.STL" />
            </geometry>
            <material name="Blue" />
        </visual>
        <collision>
            <origin xyz="0 0 0" rpy="0 0 0" />
            <geometry>
                <mesh filename="package://armbot_description/meshes/model_npoa/link_1.STL" />
            </geometry>
        </collision>
    </link>
    <joint name="joint_1" type="revolute">
        <origin xyz="0.003 0 0.0155" rpy="0 0 0" />
        <parent link="base_link" />
        <child link="link_1" />
        <axis xyz="0 0 -1" />
        <limit lower="-2.25" upper="2.25" effort="150" velocity="3.15" />
    </joint>
    <link name="link_2">

<inertial>
            <origin xyz="0.0886170464339107 0.00598587894412289 0.015250229508242" rpy="0 0 0" />
            <mass value="0.100204717943485" />
            <inertia ixx="2.61428888938491E-05" ixy="2.54454044525182E-05" ixz="1.09431351303679E-11" iyy="0.000203985287934659" iyz="-1.27442393275307E-12" izz="0.000226109263195527" />
        </inertial>

        <visual>
            <origin xyz="0 0 0" rpy="0 0 0" />
            <geometry>
                <mesh filename="package://armbot_description/meshes/model_npoa/link_2.STL" />
            </geometry>
            <material name="Grey" />
        </visual>
        <collision>
            <origin xyz="0 0 0" rpy="0 0 0" />
            <geometry>
                <mesh filename="package://armbot_description/meshes/model_npoa/link_2.STL" />
            </geometry>
        </collision>
    </link>
    <joint name="joint_2" type="revolute">
        <origin xyz="0.0026508 0.015956 0.09502" rpy="1.5708 -1.5708 0" />
        <parent link="link_1" />
        <child link="link_2" />
        <axis xyz="0 0.010019 0.99995" />
        <limit lower="-1.5708" upper="0" effort="150" velocity="3.15" />
    </joint>
    <link name="link_3">

<inertial>
            <origin xyz="0.0646747389696024 -0.0429649174871422 -0.0102416455898691" rpy="0 0 0" />
            <mass value="0.0817197581918649" />
            <inertia ixx="4.0415468488221E-05" ixy="6.56934767105951E-05" ixz="-6.53592268573663E-12" iyy="0.000201073966281048" iyz="2.86095067335606E-12" izz="0.00024012850388552" />
        </inertial>

        <visual>
            <origin xyz="0 0 0" rpy="0 0 0" />
            <geometry>
                <mesh filename="package://armbot_description/meshes/model_npoa/link_3.STL" />
            </geometry>
            <material name="Grey" />
        </visual>
        <collision>
            <origin xyz="0 0 0" rpy="0 0 0" />
            <geometry>
                <mesh filename="package://armbot_description/meshes/model_npoa/link_3.STL" />
            </geometry>
        </collision>
    </link>
    <joint name="joint_3" type="revolute">
        <origin xyz="0.13709 -0.015779 0.0061346" rpy="3.1416 0 -2.8788" />
        <parent link="link_2" />
        <child link="link_3" />
        <axis xyz="0.0026029 -0.0096749 0.99995" />
        <limit lower="-1.5708" upper="0" effort="150" velocity="3.15" />
    </joint>
    <link name="link_4">

<inertial>
            <origin xyz="0.0207581575218029 0.00678794854439591 -0.00749999999999806" rpy="0 0 0" />
            <mass value="0.0208066724716135" />
            <inertia ixx="2.86175125785257E-06" ixy="1.03093211001244E-06" ixz="-5.08716076720112E-20" iyy="8.24007040809251E-06" iyz="1.88345716755874E-19" izz="9.64616279359455E-06" />
        </inertial>

        <visual>
            <origin xyz="0 0 0" rpy="0 0 0" />
            <geometry>
                <mesh filename="package://armbot_description/meshes/model_npoa/link_4.STL" />
            </geometry>
            <material name="BlueLight" />
        </visual>
        <collision>
            <origin xyz="0 0 0" rpy="0 0 0" />
            <geometry>
                <mesh filename="package://armbot_description/meshes/model_npoa/link_4.STL" />
            </geometry>
        </collision>
    </link>
    <joint name="joint_4" type="revolute">
        <origin xyz="0.15162 -0.051106 -0.017433" rpy="3.1416 0 -1.0232" />
        <parent link="link_3" />
        <child link="link_4" />
        <axis xyz="0 0 -1" />
        <limit lower="-3.14159265" upper="3.14159265" effort="150" velocity="3.15" />
    </joint>
    <link name="link_end">

<inertial>
            <origin xyz="0 0 0" rpy="1.5708 0 0.27" />
            <mass value="0.0720522181905562" />
            <inertia ixx="4.65168177236826E-06" ixy="2.69782530922448E-07" ixz="2.26895455918749E-10" iyy="5.43707428101803E-06" iyz="1.28996353964247E-09" izz="8.25427653472157E-06" />
        </inertial>

        <visual>
            <origin xyz="0.028 0.2558 -0.0075" rpy="0 0 0.27" />
            <geometry>
                <mesh filename="package://armbot_description/meshes/model_npoa/link_end.STL" />
            </geometry>
            <material name="">
                <color rgba="0.752941176470588 0.752941176470588 0.752941176470588 1" />
            </material>
        </visual>
        <collision>
            <origin xyz="0 0 0" rpy="0 0 0" />
            <geometry>
                <mesh filename="package://armbot_description/meshes/model_npoa/link_end.STL" />
            </geometry>
        </collision>
    </link>
    <joint name="joint_end" type="fixed">
        <!--<origin
      xyz="0.02517 0.25546 -0.0075"
      rpy="0 0 0.28474" />-->
        <origin xyz="0 0 0" rpy="0 0 0" />
        <parent link="link_4" />
        <child link="link_end" />
        <axis xyz="0 0 0" />
    </joint>
    <link name="link_grip">

<inertial>
            <origin xyz="0.0020059022443632 -0.0122688289336258 0.0385866948639068" rpy="0 0 0" />
            <mass value="0.142220620437737" />
            <inertia ixx="1.22983347376849E-05" ixy="-3.17923624774908E-07" ixz="4.75415212904915E-07" iyy="1.82963683986045E-05" iyz="-5.2172700716867E-07" izz="1.47186042220067E-05" />
        </inertial>

        <visual>
            <origin xyz="0 0 0" rpy="0 0 0" />
            <geometry>
                <cylinder length="0.10" radius="0.0025" />
                <!-- <mesh
          filename="package://armbot_description/meshes/model_npoa/link_grip.STL" /> -->
            </geometry>
            <material name="Black" />
        </visual>
        <collision>
            <origin xyz="0 0 0" rpy="0 0 0" />
            <geometry>
                <cylinder length="0.10" radius="0.0025" />
                <!-- <mesh
          filename="package://armbot_description/meshes/model_npoa/link_grip.STL" /> -->
            </geometry>
        </collision>
    </link>
    <joint name="joint_grip" type="revolute">
        <origin xyz="0.0715 -0.064 -0.0075" rpy="1.5708 0 0.27" />
        <parent link="link_end" />
        <child link="link_grip" />
        <axis xyz="0 0 -1" />
        <limit lower="-1.570796325" upper="1.570796325" effort="150" velocity="3.15" />
    </joint>

<transmission name="trans_joint_1">
        <type>transmission_interface/SimpleTransmission</type>
        <joint name="joint_1">
            <hardwareInterface>hardware_interface/PositionJointInterface</hardwareInterface>
        </joint>
        <actuator name="joint_1_motor">
            <hardwareInterface>hardware_interface/PositionJointInterface</hardwareInterface>
            <mechanicalReduction>1</mechanicalReduction>
        </actuator>
    </transmission>
    <transmission name="trans_joint_2">
        <type>transmission_interface/SimpleTransmission</type>
        <joint name="joint_2">
            <hardwareInterface>hardware_interface/PositionJointInterface</hardwareInterface>
        </joint>
        <actuator name="joint_2_motor">
            <hardwareInterface>hardware_interface/PositionJointInterface</hardwareInterface>
            <mechanicalReduction>1</mechanicalReduction>
        </actuator>
    </transmission>
    <transmission name="trans_joint_3">
        <type>transmission_interface/SimpleTransmission</type>
        <joint name="joint_3">
            <hardwareInterface>hardware_interface/PositionJointInterface</hardwareInterface>
        </joint>
        <actuator name="joint_3_motor">
            <hardwareInterface>hardware_interface/PositionJointInterface</hardwareInterface>
            <mechanicalReduction>1</mechanicalReduction>
        </actuator>
    </transmission>
    <transmission name="trans_joint_4">
        <type>transmission_interface/SimpleTransmission</type>
        <joint name="joint_4">
            <hardwareInterface>hardware_interface/PositionJointInterface</hardwareInterface>
        </joint>
        <actuator name="joint_4_motor">
            <hardwareInterface>hardware_interface/PositionJointInterface</hardwareInterface>
            <mechanicalReduction>1</mechanicalReduction>
        </actuator>
    </transmission>
    <transmission name="trans_joint_grip">
        <type>transmission_interface/SimpleTransmission</type>
        <joint name="joint_grip">
            <hardwareInterface>hardware_interface/PositionJointInterface</hardwareInterface>
        </joint>
        <actuator name="joint_grip_motor">
            <hardwareInterface>hardware_interface/PositionJointInterface</hardwareInterface>
            <mechanicalReduction>1</mechanicalReduction>
        </actuator>
    </transmission>
    <gazebo>
        <plugin name="gazebo_ros_control" filename="libgazebo_ros_control.so">
            <robotNamespace>/</robotNamespace>
        </plugin>
    </gazebo>
</robot>