<?xml version="1.0" encoding="utf-8"?>
<!-- This URDF was automatically created by SolidWorks to URDF Exporter! Originally created by Stephen Brawner (brawner@gmail.com) 
     Commit Version: 1.6.0-4-g7f85cfe  Build Version: 1.6.7995.38578
     For more information, please see http://wiki.ros.org/sw_urdf_exporter -->

<robot name="armbot">

  <material name="Black">
      <color rgba="0 0 0 1"/>
  </material>

  <material name="White">
      <color rgba="1 1 1 1"/>
  </material>

  <material name="Grey">
      <color rgba="0.5 0.5 0.5 1"/>
  </material>

  <material name="Blue">
      <color rgba="0.03 0.53 0.64 1"/>
  </material>

  <material name="BlueLight">
      <color rgba="0.24 0.69 0.74 1"/>
  </material>

  <material name="Yellow">
      <color rgba="0.42 0.40 0.15 1"/>
  </material>

  <link name="world"/>

  <joint name="joint1_world" type="fixed" >
      <parent link="world"/>
      <child link="base_link"/> </joint>

  <link
    name="base_link">
    <inertial>
      <origin
        xyz="0.0211202900240581 2.59775846834193E-11 0.00380052135150776"
        rpy="0 0 0" />
      <mass
        value="0.271570047216607" />
      <inertia
        ixx="0.000442541459178714"
        ixy="-7.61202510824958E-12"
        ixz="-5.27773157069647E-07"
        iyy="0.000555892462598209"
        iyz="5.63321074251884E-15"
        izz="0.000997118891006557" />
    </inertial>
    <visual>
      <origin
        xyz="0 0 0"
        rpy="0 0 3.14" />
      <geometry>
        <mesh
          filename="package://armbot_description/meshes/model_npoa/base_link.STL" />
      </geometry>
      <material name="Yellow"/>
    </visual>
    <collision>
      <origin
        xyz="0 0 0"
        rpy="0 0 0" />
      <geometry>
        <mesh
          filename="package://armbot_description/meshes/model_npoa/base_link.STL" />
      </geometry>
    </collision>
  </link>

  <link
    name="link_1">
    <inertial>
      <origin
        xyz="-0.00272155425407784 -0.000113340999406611 -0.0586724985336868"
        rpy="0 0 0" />
      <mass
        value="0.579092466366984" />
      <inertia
        ixx="0.000456587803138105"
        ixy="-1.13087657027162E-07"
        ixz="3.16702255632446E-06"
        iyy="0.000511771419629803"
        iyz="-1.37277769518058E-06"
        izz="0.000496840287124422" />
    </inertial>
    <visual>
      <origin
        xyz="0 0 0"
        rpy="0 0 3.14" />
      <geometry>
        <mesh
          filename="package://armbot_description/meshes/model_npoa/link_1.STL" />
      </geometry>
      <material name="Blue"/>
    </visual>
    <collision>
      <origin
        xyz="0 0 0"
        rpy="0 0 0" />
      <geometry>
        <mesh
          filename="package://armbot_description/meshes/model_npoa/link_1.STL" />
      </geometry>
    </collision>
  </link>

  <joint
    name="joint_1"
    type="revolute">
    <origin
      xyz="0.003 0 0.0155"
      rpy="-3.1416 0 -3.1269" />
    <parent
      link="base_link" />
    <child
      link="link_1" />
    <axis
      xyz="0 0 -1" />
    <limit
      lower="-2.25"
      upper="2.25"
      effort="150"
      velocity="3.15" />
  </joint>

  <link
    name="link_2">
    <inertial>
      <origin
        xyz="0.0886170480813812 0.005985856672575 0.0152502295082419"
        rpy="0 0 0" />
      <mass
        value="0.100204717943486" />
      <inertia
        ixx="2.61429021289324E-05"
        ixy="2.54454507036305E-05"
        ixz="1.09431347818403E-11"
        iyy="0.000203985274699578"
        iyz="-1.27442674892586E-12"
        izz="0.000226109263195528" />
    </inertial>
    <visual>
      <origin
        xyz="0 -0.005 0"
        rpy="0 0 0" />
      <geometry>
        <mesh
          filename="package://armbot_description/meshes/model_npoa/link_2.STL" />
      </geometry>
      <material name="Grey"/>
    </visual>
    <collision>
      <origin
        xyz="0 0 0"
        rpy="0 0 0" />
      <geometry>
        <mesh
          filename="package://armbot_description/meshes/model_npoa/link_2.STL" />
      </geometry>
    </collision>
  </link>

  <joint
    name="joint_2"
    type="revolute">
    <origin
      xyz="0.0027435 0.0155 -0.09502"
      rpy="1.5708 1.5708 0" />
    <parent
      link="link_1" />
    <child
      link="link_2" />
    <axis
      xyz="0 0 1" />
    <limit
      lower="-1.5708"
      upper="0"
      effort="150"
      velocity="3.15" />
  </joint>

  <link
    name="link_3">
    <inertial>
      <origin
        xyz="0.064674729234811 -0.0429649321408343 -0.010241645589869"
        rpy="0 0 0" />
      <mass
        value="0.0817197581918697" />
      <inertia
        ixx="4.0415498257249E-05"
        ixy="6.56935131118188E-05"
        ixz="-6.5359216897847E-12"
        iyy="0.000201073936512037"
        iyz="2.86095194327021E-12"
        izz="0.000240128503885537" />
    </inertial>
    <visual>
      <origin
        xyz="0 0 0"
        rpy="0 0 0" />
      <geometry>
        <mesh
          filename="package://armbot_description/meshes/model_npoa/link_3.STL" />
      </geometry>
      <material name="Grey"/>
    </visual>
    <collision>
      <origin
        xyz="0 0 0"
        rpy="0 0 0" />
      <geometry>
        <mesh
          filename="package://armbot_description/meshes/model_npoa/link_3.STL" />
      </geometry>
    </collision>
  </link>

  <joint
    name="joint_3"
    type="revolute">
    <origin
      xyz="0.13709 -0.015779 0.0061346"
      rpy="3.1416 0 -2.8788" />
    <parent
      link="link_2" />
    <child
      link="link_3" />
    <axis
      xyz="0.0026029 -0.0096749 0.99995" />
    <limit
      lower="-1.5708"
      upper="0"
      effort="150"
      velocity="3.15" />
  </joint>
  <link
    name="link_4">
    <inertial>
      <origin
        xyz="-0.00375610824670326 0.0215143905323992 0.00749999999999806"
        rpy="0 0 0" />
      <mass
        value="0.0208066724716135" />
      <inertia
        ixx="6.19890674797337E-06"
        ixy="2.80615422421083E-06"
        ixz="-1.89885927056448E-19"
        iyy="4.90291491797169E-06"
        iyz="-4.33905862120816E-20"
        izz="9.64616279359452E-06" />
    </inertial>
    <visual>
      <origin
        xyz="0 0 0"
        rpy="0 0 0" />
      <geometry>
        <mesh
          filename="package://armbot_description/meshes/model_npoa/link_4.STL" />
      </geometry>
      <material name="BlueLight"/>
    </visual>
    <collision>
      <origin
        xyz="0 0 0"
        rpy="0 0 0" />
      <geometry>
        <mesh
          filename="package://armbot_description/meshes/model_npoa/link_4.STL" />
      </geometry>
    </collision>
  </link>

  <joint
    name="joint_4"
    type="revolute">
    <origin
      xyz="0.15162 -0.051106 -0.017433"
      rpy="0 0 -3.0829" />
    <parent
      link="link_3" />
    <child
      link="link_4" />
    <axis
      xyz="0 0 1" />
    <limit
      lower="-3.14159265"
      upper="3.14159265"
      effort="150"
      velocity="3.15" />
  </joint>
  
  <link
    name="link_end">
    <inertial>
      <origin
        xyz="-0.0483151025046168 -0.219886709667518 3.40719887590205E-05"
        rpy="0 0 0" />
      <mass
        value="0.0720522181905562" />
      <inertia
        ixx="4.65168177236826E-06"
        ixy="2.69782530922447E-07"
        ixz="2.26895455918722E-10"
        iyy="5.43707428101803E-06"
        iyz="1.28996353964216E-09"
        izz="8.25427653472157E-06" />
    </inertial>
    <visual>
      <origin
        xyz="0 0 0"
        rpy="0 0 0" />
      <geometry>
        <mesh
          filename="package://armbot_description/meshes/model_npoa/link_end.STL" />
      </geometry>
      <material
        name="">
        <color
          rgba="0.752941176470588 0.752941176470588 0.752941176470588 1" />
      </material>
    </visual>
    <collision>
      <origin
        xyz="0 0 0"
        rpy="0 0 0" />
      <geometry>
        <mesh
          filename="package://armbot_description/meshes/model_npoa/link_end.STL" />
      </geometry>
    </collision>
  </link>

  <joint
    name="joint_end"
    type="fixed">
    <origin
      xyz="0.21371 0.14219 0.0075"
      rpy="-3.1416 0 1.7749" />
    <parent
      link="link_4" />
    <child
      link="link_end" />
    <axis
      xyz="0 0 0" />
  </joint>
  
  <link
    name="link_grip">
    <inertial>
      <origin
        xyz="0.00200590224436334 -0.0122688289336258 0.0385866948639068"
        rpy="0 0 0" />
      <mass
        value="0.142220620437737" />
      <inertia
        ixx="1.22983347376849E-05"
        ixy="-3.17923624774908E-07"
        ixz="4.75415212904915E-07"
        iyy="1.82963683986045E-05"
        iyz="-5.2172700716867E-07"
        izz="1.47186042220067E-05" />
    </inertial>
    <visual>
      <origin
        xyz="0 0 0"
        rpy="0 0 0" />
      <geometry>
        <mesh
          filename="package://armbot_description/meshes/model_npoa/link_grip.STL" />
      </geometry>
      <material name="Black"/>
    </visual>
    <collision>
      <origin
        xyz="0 0 0"
        rpy="0 0 0" />
      <geometry>
        <mesh
          filename="package://armbot_description/meshes/model_npoa/link_grip.STL" />
      </geometry>
    </collision>
  </link>

  <joint
    name="joint_grip"
    type="revolute">
    <origin
      xyz="-0.043378 -0.23321 0"
      rpy="1.5708 0 0" />
    <parent
      link="link_end" />
    <child
      link="link_grip" />
    <axis
      xyz="0 0 -1" />
    <limit
      lower="-1.570796325"
      upper="1.570796325"
      effort="150"
      velocity="3.15" />
  </joint>
</robot>