<?xml version="1.0" encoding="utf-8"?>
<!-- This URDF was automatically created by SolidWorks to URDF Exporter! Originally created by Stephen Brawner (brawner@gmail.com) 
     Commit Version: 1.6.0-4-g7f85cfe  Build Version: 1.6.7995.38578
     For more information, please see http://wiki.ros.org/sw_urdf_exporter -->
<robot name="armbot">

    <!-- Defining the colors used in this robot -->
    <material name="Black">
        <color rgba="0 0 0 1"/>
    </material>

    <material name="White">
        <color rgba="1 1 1 1"/>
    </material>

    <material name="Grey">
        <color rgba="0.5 0.5 0.5 1"/>
    </material>

  <link name="world"/>

  <joint name="joint1_world" type="fixed" >
      <parent link="world"/>
      <child link="base_link"/> 
  </joint>

  <link name="base_link">
    <visual>
      <origin xyz="0 0 0" rpy="0 0 0" />
      <geometry>
        <mesh filename="package://armbot_description/meshes/model_npoa/base_link.STL" />
      </geometry>
      <material name="White" />
    </visual>
    <collision>
      <origin xyz="0 0 0" rpy="0 0 0" />
      <geometry>
        <mesh filename="package://armbot_description/meshes/model_npoa/base_link.STL" />
      </geometry>
    </collision>
  </link>

  <link name="link_1">
    <visual>
      <origin xyz="0 0 0" rpy="0 0 0" />
      <geometry>
        <mesh filename="package://armbot_description/meshes/model_npoa/link_1.STL" />
      </geometry>
      <material name="White" />
    </visual>
    <collision>
      <origin xyz="0 0 0" rpy="0 0 0" />
      <geometry>
        <mesh filename="package://armbot_description/meshes/model_npoa/link_1.STL" />
      </geometry>
    </collision>
  </link>

  <joint name="joint_1" type="revolute">
    <origin xyz="0 0 0.003" rpy="-1.5708 0 0.014721" />
    <parent link="base_link" />
    <child link="link_1" />
    <axis xyz="0 1 0" />
    <limit effort="150.0" lower="-2.25" upper="2.25" velocity="3.15"/>
  </joint>

  <link name="link_2">
    <visual>
      <origin xyz="0 0 0" rpy="0 0 0" />
      <geometry>
        <mesh filename="package://armbot_description/meshes/model_npoa/link_2.STL" />
      </geometry>
      <material name="Grey" />
    </visual>
    <collision>
      <origin
        xyz="0 0 0"
        rpy="0 0 0" />
      <geometry>
        <mesh filename="package://armbot_description/meshes/model_npoa/link_2.STL" />
      </geometry>
    </collision>
  </link>

  <joint name="joint_2" type="revolute">
    <origin
      xyz="0 -0.086784 0"
      rpy="-3.1416 0 0.44762" />
    <parent link="link_1" />
    <child link="link_2" />
    <axis xyz="0 0 1"/>
    <!-- axis xyz="0.43282 -0.90148 0" /-->
    <limit effort="150.0" lower="0" upper="1.570796325" velocity="3.15"/>
  </joint>

  <link name="link_3">
    <visual>
      <origin
        xyz="0 0 0"
        rpy="0 0 0" />
      <geometry>
        <mesh filename="package://armbot_description/meshes/model_npoa/link_3.STL" />
      </geometry>
      <material name="White" />
    </visual>
    <collision>
      <origin
        xyz="0 0 0"
        rpy="0 0 0" />
      <geometry>
        <mesh filename="package://armbot_description/meshes/model_npoa/link_3.STL" />
      </geometry>
    </collision>
  </link>

  <joint name="joint_3" type="revolute">
    <origin
      xyz="-0.14546 0.11597 -6.7308E-05"
      rpy="0 0 -1.7541" />
    <parent link="link_2" />
    <child link="link_3" />
    <axis xyz="0 0 1" />
    <limit effort="150.0" lower="0" upper="1.570796325" velocity="3.15"/>
  </joint>

  <link name="link_4">
    <visual>
      <origin
        xyz="-0.21 0.025  0"
        rpy="0 0 1.57" />
      <geometry>
        <mesh filename="package://armbot_description/meshes/model_npoa/link_4.STL" />
      </geometry>
      <material name="Grey" />
    </visual>
    <collision>
      <origin
        xyz="0 0 0"
        rpy="0 0 0" />
      <geometry>
        <mesh filename="package://armbot_description/meshes/model_npoa/link_4.STL" />
      </geometry>
    </collision>
  </link>

  <joint name="joint_4" type="revolute">
    <origin
      xyz="0.165 0 0"
      rpy="0 0 0" />
    <parent link="link_3" />
    <child link="link_4" />
    <axis xyz="0 0 1"/>
    <limit effort="150.0" lower="-3.14159265" upper="3.14159265" velocity="3.15"/>
  </joint>

  <link name="link_end">
    <visual>
      <origin
        xyz="0 0 0"
        rpy="0 0 0" />
      <geometry>
        <mesh filename="package://armbot_description/meshes/model_npoa/link_end.STL" />
      </geometry>
      <material name="Black"/>
    </visual>
    <collision>
      <origin
        xyz="0 0 0"
        rpy="0 0 0" />
      <geometry>
        <mesh filename="package://armbot_description/meshes/model_npoa/link_end.STL" />
      </geometry>
    </collision>
  </link>

  <joint name="joint_end" type="fixed">
    <origin
      xyz="0 0 0"
      rpy="0 0 0" />
    <parent link="link_4" />
    <child link="link_end" />
  </joint>
  <link name="link_grip">
    <visual>
      <origin
        xyz="0 0 0"
        rpy="0 0 0" />
      <geometry>
        <mesh filename="package://armbot_description/meshes/model_npoa/link_grip.STL" />
      </geometry>
      <material name="Black"/>
    </visual>
    <collision>
      <origin
        xyz="0 0 0"
        rpy="0 0 0" />
      <geometry>
        <mesh filename="package://armbot_description/meshes/model_npoa/link_grip.STL" />
      </geometry>
    </collision>
  </link>

  <joint name="joint_grip" type="revolute">
    <origin
      xyz="0.035 -0.034 -0.0055"
      rpy="0 1.6 1.55" />
    <parent link="link_end" />
    <child link="link_grip" />
    <axis xyz="0 1 0"/>
    <limit effort="150.0" lower="-1.570796325" upper="1.570796325" velocity="3.15"/>
  </joint>
</robot>